<?xml version="1.0"?>
 <robot name="Bunny">

<!-- This defines the color of the body  -->
 
 <material name="black">
   <color rgba="0 0 0 1"/>
 </material>
 <material name="red">
   <color rgba="1 0 0 1"/>
 </material>

<!-- Gazebo references for colors for the robot-->

<gazebo reference="base_link">
   <material>Gazebo/Red</material>
</gazebo>
<gazebo reference="wheel_1">
   <material>Gazebo/Black</material>
</gazebo>
<gazebo reference="wheel_2">
   <material>Gazebo/Black</material>
</gazebo>
<gazebo reference="wheel_3">
   <material>Gazebo/Black</material>
</gazebo>
<gazebo reference="wheel_4">
   <material>Gazebo/Black</material>
</gazebo>

<!-- Gazebo plugin for controlling the robot with keyboard -->
<gazebo>
    <plugin filename="libgazebo_ros_diff_drive.so" name="differential_drive_controller">
      <alwaysOn>true</alwaysOn>
      <updateRate>20</updateRate>
      <leftJoint>base_to_wheel1</leftJoint>
      <rightJoint>base_to_wheel2</rightJoint>
      <wheelSeparation>0.3</wheelSeparation>
      <wheelDiameter>0.08</wheelDiameter>
      <wheelAcceleration>1.0</wheelAcceleration>
      <wheelTorque>10</wheelTorque>
      <legacyMode>false</legacyMode>
      <commandTopic>cmd_vel</commandTopic>
      <odometryTopic>odom</odometryTopic>
      <odometryFrame>odom</odometryFrame>
      <robotBaseFrame>base_link</robotBaseFrame>
      <odometrySource>1</odometrySource>
      <publishWheelTF>true</publishWheelTF>
      <publishOdom>true</publishOdom>
      <publishWheelJointState>true</publishWheelJointState>
    </plugin>
</gazebo>

<gazebo reference="sensor_laser">
    <sensor type="ray" name="head_hokuyo_sensor">
      <pose>0 0 0 0 0 0</pose>
      <visualize>true</visualize>
      <update_rate>10</update_rate>
      <ray>
        <scan>
          <horizontal>
            <samples>720</samples>
            <resolution>1</resolution>
            <min_angle>-3.14159265</min_angle>
            <max_angle>3.14159265</max_angle>
          </horizontal>
        </scan>
        <range>
          <min>0.10</min>
          <max>10.0</max>
          <resolution>0.01</resolution>
        </range>
        <noise>
          <type>gaussian</type>
          <mean>0.0</mean>
          <stddev>0.01</stddev>
        </noise>
      </ray>
      <plugin name="gazebo_ros_head_hokuyo_controller" filename="libgazebo_ros_laser.so">
        <topicName>/bunny/laser/scan</topicName>
        <frameName>sensor_laser</frameName>
      </plugin>
    </sensor>
  </gazebo> 





<link name="base_link">
   <visual>
      <geometry>
         <box size= "0.2 0.3 0.1"/>
      </geometry> 
      <origin rpy="0 0 0" xyz="0 0 0"/>
      <material name="red"/>
   </visual>
   <collision name="collision_chasis">
      <geometry> 
         <box size="0.2 0.3 0.1"/>
      </geometry>
      <material name="red"/>
   </collision>
   <inertial>
      <mass value="1.0"/> 
      <inertia ixx="1.5e-3" iyy="4.1667e-3" izz="5.4167e-4"
         ixy="0" ixz="0" iyz="0"/>  
   </inertial>
  </link> 
  
  <link name="wheel_1"> 
      <visual>
         <geometry>
            <cylinder length="0.04" radius="0.04"/>
         </geometry>
         <origin rpy="0 1.57079633 0" xyz="0.0 0.0 0.0"/>
         <material name="black"/>
      </visual>
      <collision name="wheel1_collision">
         <geometry>
            <cylinder length="0.04" radius="0.04"/>
         </geometry>
         <origin rpy="0 1.57079633 0" xyz="0.0 0.0 0.0"/>
      </collision>
      <inertial>
         <mass value="0.1"/>
         <origin rpy="0 1.57079633 0" xyz="0.0 0.0 0.0"/>
         <inertia ixx="5.333e-5" iyy="5.333e-5" izz="8.00e-5" 
         ixy="0" ixz="0" iyz="0"/>
      </inertial>
  </link>

  <joint name="base_to_wheel1" type="continuous">
   <axis xyz="1 0 0"/>
   <parent link="base_link"/>
   <child link="wheel_1"/>
   <origin rpy="0 0 0" xyz="0.1 0.09 -0.04"/>
  </joint> 

  <link name="wheel_2"> 
      <visual>
         <geometry>
            <cylinder length="0.04" radius="0.04"/>
         </geometry>
         <origin rpy="0 1.57079633 0" xyz="0.0 0.0 0.0"/>
         <material name="black"/>
      </visual>
      <collision name="wheel2_collision">
         <geometry>
            <cylinder length="0.04" radius="0.04"/>
         </geometry>
         <origin rpy="0 1.57079633 0" xyz="0.0 0.0 0.0"/>
      </collision>
      <inertial>
         <mass value="0.1"/>
         <origin rpy="0 1.57079633 0" xyz="0.0 0.0 0.0"/>
         <inertia ixx="5.333e-5" iyy="5.333e-5" izz="8.00e-5" 
         ixy="0" ixz="0" iyz="0"/>
      </inertial>
  </link>

  <joint name="base_to_wheel2" type="continuous">
   <axis xyz="1 0 0"/>
   <parent link="base_link"/>
   <child link="wheel_2"/>
   <origin rpy="0 0 0" xyz="-0.1 0.09 -0.04"/>
  </joint>

  <link name="wheel_3"> 
      <visual>
         <geometry>
            <cylinder length="0.04" radius="0.04"/>
         </geometry>
         <origin rpy="0 1.57079633 0" xyz="0.0 0.0 0.0"/>
         <material name="black"/>
      </visual>
      <collision name="wheel3_collision">
         <geometry>
            <cylinder length="0.04" radius="0.04"/>
         </geometry>
         <origin rpy="0 1.57079633 0" xyz="0.0 0.0 0.0"/>
      </collision>
      <inertial>
         <mass value="0.1"/>
         <origin rpy="0 1.57079633 0" xyz="0.0 0.0 0.0"/>
         <inertia ixx="5.333e-5" iyy="5.333e-5" izz="8.00e-5" 
         ixy="0" ixz="0" iyz="0"/>
      </inertial>
  </link>

  <joint name="base_to_wheel3" type="continuous">
   <axis xyz="1 0 0"/>
   <parent link="base_link"/>
   <child link="wheel_3"/>
   <origin rpy="0 0 0" xyz="0 -0.09 -0.04"/>
  </joint>

  <link name="sensor_laser">
   <collision>
      <origin xyz="0 0 0" rpy="0 0 0"/>
   <geometry>
      <box size="0.1 0.1 0.1"/>
   </geometry>
  </collision>
   <visual>
      <origin xyz="0 0 0" rpy="0 0 0"/>
      <geometry>
         <box size="0.1 0.1 0.1"/>
      </geometry>
   </visual>
   <inertial>
      <mass value="1e-5" />
      <origin xyz="0 0 0" rpy="0 0 0"/>
      <inertia ixx="1e-6" ixy="0" ixz="0" iyy="1e-6" iyz="0" izz="1e-6" />
   </inertial>
   </link>

   <joint name="joint_sensor_laser" type="fixed">
      <axis xyz="0 1 0" />
      <origin xyz="0 0 0.08" rpy="0 0 -1.57"/>
      <parent link="base_link"/>
      <child link="sensor_laser"/>
   </joint>

   <!-- <joint name="camera_joint" type="fixed">
    <axis xyz="0 1 0" />
    <origin xyz="0.05 -0.125 0.025" rpy="0 0 0"/>
    <parent link="base_link"/>
    <child link="camera_link"/>
  </joint> -->

  <!-- Camera -->
  <!-- <link name="camera_link">
    <collision>
      <origin xyz="0 0 0" rpy="0 0 0"/>
      <geometry>
    <box size="0.05 0.05 0.05"/>
      </geometry>
    </collision>

    <visual>
      <origin xyz="0 0 0" rpy="0 0 0"/>
      <geometry>
    <box size="0.05 0.05 0.05"/>
      </geometry>
      <material name="black"/>
    </visual>

    <inertial>
      <mass value="1e-5" />
      <origin xyz="0 0 0" rpy="0 0 0"/>
      <inertia ixx="1e-6" ixy="0" ixz="0" iyy="1e-6" iyz="0" izz="1e-6" />
    </inertial>
  </link>

  <gazebo reference="camera_link">
    <sensor type="camera" name="camera1">
      <update_rate>30.0</update_rate>
      <camera name="head">
        <horizontal_fov>1.3962634</horizontal_fov>
        <image>
          <width>800</width>
          <height>800</height>
          <format>R8G8B8</format>
        </image>
        <clip>
          <near>0.02</near>
          <far>300</far>
        </clip>
        <noise>
          <type>gaussian</type>
           Noise is sampled independently per pixel on each frame.
               That pixel's noise value is added to each of its color
               channels, which at that point lie in the range [0,1]. -->
          <!-- <mean>0.0</mean>
          <stddev>0.007</stddev>
        </noise>
      </camera>
      <plugin name="camera_controller" filename="libgazebo_ros_camera.so">
        <alwaysOn>true</alwaysOn>
        <updateRate>0.0</updateRate>
        <cameraName>rrbot/camera1</cameraName>
        <imageTopicName>image_raw</imageTopicName>
        <cameraInfoTopicName>camera_info</cameraInfoTopicName>
        <frameName>camera_link</frameName>
        <hackBaseline>0.07</hackBaseline>
        <distortionK1>0.0</distortionK1>
        <distortionK2>0.0</distortionK2>
        <distortionK3>0.0</distortionK3>
        <distortionT1>0.0</distortionT1>
        <distortionT2>0.0</distortionT2>
      </plugin>
    </sensor>
  </gazebo> 
 -->

</robot> 


    
 
  